Workbook
Name CONEAU_EV_ID: Ref_EV!$A$2:$A$53
Name CONEAU_EV_EST: Ref_EV!$B$2:$B$53
Name CONEAU_EV_DESC: Ref_EV!$C$2:$C$53

Sheet Leeme
A1: SGC · Plantilla de carga por escuela
A2: Versión 0.6, 20-10-2026. Propuesta [CP] para las Escuelas de Tecnología Médica, Enfermería y Obstetricia · Facultad de Medicina, UNMSM
A4: Para qué sirve | B4: Cada escuela carga aquí sus mediciones, el estado de sus evidencias y su alcance. El tablero HTML consolida los archivos de las tres escuelas (y el de la Facultad) y calcula estados, alertas y trazabilidad.
A5: Qué se llena | B5: Solo las celdas azules sobre fondo amarillo claro. Hojas: Portada (1 vez), Carga_Indicadores (una fila por indicador, periodo y área), Evidencias (EV1 a EV52 por área), Alcance (qué indicadores se vigilan), Criterios (53 criterios del modelo; «sin dato» hasta que haya informe) y Valores_informe (29 ID; solo referencia).
A6: Qué NO se toca | B6: Catalogo, Listas y Relaciones son de consulta. Parametros, Reglas_alertas y Metas_Umbrales las edita el comité de calidad de la Facultad: si cambias algo, cambia la fecha_parametros.
A7: Regla de oro | B7: Todo dato lleva su fuente (columna fuente_dato). Una fila sin fuente no se muestra como dato en el tablero. Una meta propuesta lleva su fuente_meta; sin fuente se ignora.
A8: Periodos | B8: Anual 2025 · semestre 2025-S1 · trimestre 2025-T2 · mes 2026-02. El tablero compara por la fecha de cierre del periodo. El calendario académico de la UNMSM está por confirmar [CP].
A9: Avance esperado | B9: Para indicadores que se acumulan en el año (en Metas_Umbrales, tipo_avance = Acumulado en el año), el tablero compara con lo esperado a la fecha de corte y no con la meta anual, para evitar falsos rojos con datos parciales. Si tienes el esperado a la fecha (por ejemplo, lo programado acumulado en el plan operativo), escríbelo en esperado_a_fecha con su fuente_esperado. Si no lo traes, en los indicadores del PE FM el tablero usa el programado acumulado al corte del POI mensual de la Facultad (no el 0,5 del año); sin POI mensual vinculado el indicador queda «En seguimiento», no en rojo. Los indicadores Puntuales se comparan directo con la meta.
A10: Regla de cumplimiento | B10: En Metas_Umbrales, regla_cumplimiento: «Razón al esperado» (lo habitual); en los tiempos ID25 e ID26 cumple si el valor es menor o igual al referencial; en la variación ID6 cumple si no es negativa. La ficha del Modelo dice «menor a» en ID25 e ID26: el caso de igualdad está por confirmar con la OCAA.
A11: Formatos oficiales | B11: Esta plantilla es una propuesta de carga: no es un formato oficial de la UNMSM ni de la Facultad, y no lleva código de formato. Donde exista un formato oficial (Manual FM, UPPR) se usará y se citará su código. Códigos y formato por confirmar con la UPPR.
A12: Valor | B12: Escribe numerador y denominador (el valor se calcula, ×100 si la unidad es %) o escribe el valor directo. No escribas el signo %.
A13: Estado de validación | B13: Borrador (recién cargado) · Observado (con reparo) · Validado (revisado por quien corresponde; indica quién y cuándo).
A14: Evidencia | B14: Código EV del modelo CONEAU (lista desplegable) y la referencia del archivo o enlace donde está. Sin evidencia, el tablero genera una alerta.
A15: Datos de ejemplo | B15: Las filas con origen EJEMPLO son inventadas para probar el tablero. El interruptor del tablero las apaga. Bórralas antes de cargar datos reales.
... A18: Fuentes | B18: A4 modelo CONEAU 2026; A8 MAGPROF; A11 PE FM 2024-2027; A12 PEI UNMSM 2026-2030; A14, A15, A16 reportes del POI. Claves completas en el tablero.

Sheet Portada
A1: Portada del archivo de carga
A2: Se llena una vez por archivo.
A4: campo | B4: valor | C4: ayuda
A5: version_plantilla | B5: 0.6 | C5: No se cambia. El tablero la lee para saber si el archivo es compatible.
A6: escuela_id | B6: OBS | C6: Elige ENF, OBS, TM o FAC (Facultad, marco común).
A7: nombre_escuela | B7: =IFERROR(INDEX(Listas!$G$2:$G$5,MATCH(B6,Listas!$F$2:$F$5,0)),"") | C7: Se calcula.
A8: responsable_calidad | B8: EJEMPLO Coordinación de calidad | C8: Persona que entrega el archivo. Cargo, no datos personales sensibles.
A9: fecha_entrega | B9: 46309 | C9: Fecha en que se entrega el archivo.
A10: nota | B10: EJEMPLO: datos inventados para probar el tablero | C10: Libre.

Sheet Carga_Indicadores
A1: Carga de indicadores
A2: Una fila por indicador, periodo y área. Amarillo: se llena. Gris: se calcula. Sin fuente_dato, la fila no se muestra como dato en el tablero.
A4: periodo | B4: area_id | C4: indicador_id | D4: numerador | E4: denominador | F4: valor_directo | G4: meta_propuesta | H4: fuente_meta | I4: fuente_dato | J4: evidencia_ev | K4: evidencia_ref | L4: responsable_carga | M4: fecha_carga | N4: estado_validacion | O4: validado_por | P4: fecha_validacion | Q4: version_dato | R4: observacion | S4: origen | T4: esperado_a_fecha | U4: fuente_esperado | V4: indicador | W4: unidad | X4: valor_calculado | Y4: control
A5: 2023 | C5: ID1 | D5: 47 | E5: 85 | I5: EJEMPLO Encuesta o registro de la escuela, periodo 2023 | L5: EJEMPLO Coord. de calidad de Obstetricia | M5: 45299 | N5: Validado | O5: EJEMPLO Dirección de Escuela de Obstetricia | P5: 45308 | Q5: 1 | S5: EJEMPLO | V5: =IF(C5="","",IFERROR(INDEX(Catalogo!$C$5:$C$129,MATCH(C5,Catalogo!$A$5:$A$129,0)),"Código no existe")) | W5: =IF(C5="","",IFERROR(INDEX(Catalogo!$G$5:$G$129,MATCH(C5,Catalogo!$A$5:$A$129,0)),"")) | X5: =IF(C5="","",IF(ISNUMBER(F5),F5,IF(AND(ISNUMBER(D5),ISNUMBER(E5),E5>0),D5/E5*IF(W5="%",100,1),IF(ISNUMBER(D5),D5,"")))) | Y5: =IF(C5="","",IF(A5="","Falta periodo",IF(COUNTIF(Listas!$A$2:$A$134,A5)=0,"Periodo no válido",IF(X5="","Falta valor",IF(I5="","Falta fuente: no se mostrará",IF(AND(J5="",K5=""),"Sin evidencia",IF(N5<>"Validado","Sin validar","OK")))))))
A6: 2024 | C6: ID1 | D6: 75 | E6: 120 | I6: EJEMPLO Encuesta o registro de la escuela, periodo 2024 | J6: EV41 | K6: EJEMPLO_ID1_2024.pdf | L6: EJEMPLO Coord. de calidad de Obstetricia | M6: 45673 | N6: Observado | Q6: 1 | S6: EJEMPLO | V6: =IF(C6="","",IFERROR(INDEX(Catalogo!$C$5:$C$129,MATCH(C6,Catalogo!$A$5:$A$129,0)),"Código no existe")) | W6: =IF(C6="","",IFERROR(INDEX(Catalogo!$G$5:$G$129,MATCH(C6,Catalogo!$A$5:$A$129,0)),"")) | X6: =IF(C6="","",IF(ISNUMBER(F6),F6,IF(AND(ISNUMBER(D6),ISNUMBER(E6),E6>0),D6/E6*IF(W6="%",100,1),IF(ISNUMBER(D6),D6,"")))) | Y6: =IF(C6="","",IF(A6="","Falta periodo",IF(COUNTIF(Listas!$A$2:$A$134,A6)=0,"Periodo no válido",IF(X6="","Falta valor",IF(I6="","Falta fuente: no se mostrará",IF(AND(J6="",K6=""),"Sin evidencia",IF(N6<>"Validado","Sin validar","OK")))))))
A7: 2025 | C7: ID1 | D7: 88 | E7: 150 | I7: EJEMPLO Encuesta o registro de la escuela, periodo 2025 | J7: EV13 | K7: EJEMPLO_ID1_2025.pdf | L7: EJEMPLO Coord. de calidad de Obstetricia | M7: 46036 | N7: Validado | O7: EJEMPLO Dirección de Escuela de Obstetricia | P7: 46044 | Q7: 1 | S7: EJEMPLO | V7: =IF(C7="","",IFERROR(INDEX(Catalogo!$C$5:$C$129,MATCH(C7,Catalogo!$A$5:$A$129,0)),"Código no existe")) | W7: =IF(C7="","",IFERROR(INDEX(Catalogo!$G$5:$G$129,MATCH(C7,Catalogo!$A$5:$A$129,0)),"")) | X7: =IF(C7="","",IF(ISNUMBER(F7),F7,IF(AND(ISNUMBER(D7),ISNUMBER(E7),E7>0),D7/E7*IF(W7="%",100,1),IF(ISNUMBER(D7),D7,"")))) | Y7: =IF(C7="","",IF(A7="","Falta periodo",IF(COUNTIF(Listas!$A$2:$A$134,A7)=0,"Periodo no válido",IF(X7="","Falta valor",IF(I7="","Falta fuente: no se mostrará",IF(AND(J7="",K7=""),"Sin evidencia",IF(N7<>"Validado","Sin validar","OK")))))))
A8: 2023 | C8: ID2 | D8: 205 | E8: 320 | I8: EJEMPLO Encuesta o registro de la escuela, periodo 2023 | J8: EV38 | K8: EJEMPLO_ID2_2023.pdf | L8: EJEMPLO Coord. de calidad de Obstetricia | M8: 45318 | N8: Validado | O8: EJEMPLO Dirección de Escuela de Obstetricia | P8: 45324 | Q8: 1 | S8: EJEMPLO | V8: =IF(C8="","",IFERROR(INDEX(Catalogo!$C$5:$C$129,MATCH(C8,Catalogo!$A$5:$A$129,0)),"Código no existe")) | W8: =IF(C8="","",IFERROR(INDEX(Catalogo!$G$5:$G$129,MATCH(C8,Catalogo!$A$5:$A$129,0)),"")) | X8: =IF(C8="","",IF(ISNUMBER(F8),F8,IF(AND(ISNUMBER(D8),ISNUMBER(E8),E8>0),D8/E8*IF(W8="%",100,1),IF(ISNUMBER(D8),D8,"")))) | Y8: =IF(C8="","",IF(A8="","Falta periodo",IF(COUNTIF(Listas!$A$2:$A$134,A8)=0,"Periodo no válido",IF(X8="","Falta valor",IF(I8="","Falta fuente: no se mostrará",IF(AND(J8="",K8=""),"Sin evidencia",IF(N8<>"Validado","Sin validar","OK")))))))
A9: 2024 | C9: ID2 | D9: 146 | E9: 210 | I9: EJEMPLO Encuesta o registro de la escuela, periodo 2024 | J9: EV41 | K9: EJEMPLO_ID2_2024.pdf | L9: EJEMPLO Coord. de calidad de Obstetricia | M9: 45676 | N9: Validado | O9: EJEMPLO Dirección de Escuela de Obstetricia | P9: 45678 | Q9: 1 | S9: EJEMPLO | V9: =IF(C9="","",IFERROR(INDEX(Catalogo!$C$5:$C$129,MATCH(C9,Catalogo!$A$5:$A$129,0)),"Código no existe")) | W9: =IF(C9="","",IFERROR(INDEX(Catalogo!$G$5:$G$129,MATCH(C9,Catalogo!$A$5:$A$129,0)),"")) | X9: =IF(C9="","",IF(ISNUMBER(F9),F9,IF(AND(ISNUMBER(D9),ISNUMBER(E9),E9>0),D9/E9*IF(W9="%",100,1),IF(ISNUMBER(D9),D9,"")))) | Y9: =IF(C9="","",IF(A9="","Falta periodo",IF(COUNTIF(Listas!$A$2:$A$134,A9)=0,"Periodo no válido",IF(X9="","Falta valor",IF(I9="","Falta fuente: no se mostrará",IF(AND(J9="",K9=""),"Sin evidencia",IF(N9<>"Validado","Sin validar","OK")))))))
A10: 2025 | C10: ID2 | D10: 33 | E10: 48 | I10: EJEMPLO Encuesta o registro de la escuela, periodo 2025 | J10: EV13 | K10: EJEMPLO_ID2_2025.pdf | L10: EJEMPLO Coord. de calidad de Obstetricia | M10: 46044 | N10: Validado | O10: EJEMPLO Dirección de Escuela de Obstetricia | P10: 46045 | Q10: 1 | S10: EJEMPLO | V10: =IF(C10="","",IFERROR(INDEX(Catalogo!$C$5:$C$129,MATCH(C10,Catalogo!$A$5:$A$129,0)),"Código no existe")) | W10: =IF(C10="","",IFERROR(INDEX(Catalogo!$G$5:$G$129,MATCH(C10,Catalogo!$A$5:$A$129,0)),"")) | X10: =IF(C10="","",IF(ISNUMBER(F10),F10,IF(AND(ISNUMBER(D10),ISNUMBER(E10),E10>0),D10/E10*IF(W10="%",100,1),IF(ISNUMBER(D10),D10,"")))) | Y10: =IF(C10="","",IF(A10="","Falta periodo",IF(COUNTIF(Listas!$A$2:$A$134,A10)=0,"Periodo no válido",IF(X10="","Falta valor",IF(I10="","Falta fuente: no se mostrará",IF(AND(J10="",K10=""),"Sin evidencia",IF(N10<>"Validado","Sin validar","OK")))))))
A11: 2023 | C11: ID3 | D11: 42 | E11: 85 | I11: EJEMPLO Encuesta o registro de la escuela, periodo 2023 | J11: EV21 | K11: EJEMPLO_ID3_2023.pdf | L11: EJEMPLO Coord. de calidad de Obstetricia | M11: 45314 | N11: Validado | O11: EJEMPLO Dirección de Escuela de Obstetricia | P11: 45319 | Q11: 1 | S11: EJEMPLO | V11: =IF(C11="","",IFERROR(INDEX(Catalogo!$C$5:$C$129,MATCH(C11,Catalogo!$A$5:$A$129,0)),"Código no existe")) | W11: =IF(C11="","",IFERROR(INDEX(Catalogo!$G$5:$G$129,MATCH(C11,Catalogo!$A$5:$A$129,0)),"")) | X11: =IF(C11="","",IF(ISNUMBER(F11),F11,IF(AND(ISNUMBER(D11),ISNUMBER(E11),E11>0),D11/E11*IF(W11="%",100,1),IF(ISNUMBER(D11),D11,"")))) | Y11: =IF(C11="","",IF(A11="","Falta periodo",IF(COUNTIF(Listas!$A$2:$A$134,A11)=0,"Periodo no válido",IF(X11="","Falta valor",IF(I11="","Falta fuente: no se mostrará",IF(AND(J11="",K11=""),"Sin evidencia",IF(N11<>"Validado","Sin validar","OK")))))))
A12: 2024 | C12: ID3 | D12: 27 | E12: 60 | I12: EJEMPLO Encuesta o registro de la escuela, periodo 2024 | J12: EV38 | K12: EJEMPLO_ID3_2024.pdf | L12: EJEMPLO Coord. de calidad de Obstetricia | M12: 45680 | N12: Validado | O12: EJEMPLO Dirección de Escuela de Obstetricia | P12: 45683 | Q12: 1 | S12: EJEMPLO | V12: =IF(C12="","",IFERROR(INDEX(Catalogo!$C$5:$C$129,MATCH(C12,Catalogo!$A$5:$A$129,0)),"Código no existe")) | W12: =IF(C12="","",IFERROR(INDEX(Catalogo!$G$5:$G$129,MATCH(C12,Catalogo!$A$5:$A$129,0)),"")) | X12: =IF(C12="","",IF(ISNUMBER(F12),F12,IF(AND(ISNUMBER(D12),ISNUMBER(E12),E12>0),D12/E12*IF(W12="%",100,1),IF(ISNUMBER(D12),D12,"")))) | Y12: =IF(C12="","",IF(A12="","Falta periodo",IF(COUNTIF(Listas!$A$2:$A$134,A12)=0,"Periodo no válido",IF(X12="","Falta valor",IF(I12="","Falta fuente: no se mostrará",IF(AND(J12="",K12=""),"Sin evidencia",IF(N12<>"Validado","Sin validar","OK")))))))
A13: 2025 | C13: ID3 | D13: 70 | E13: 150 | I13: EJEMPLO Encuesta o registro de la escuela, periodo 2025 | J13: EV41 | K13: EJEMPLO_ID3_2025.pdf | L13: EJEMPLO Coord. de calidad de Obstetricia | M13: 46032 | N13: Validado | O13: EJEMPLO Dirección de Escuela de Obstetricia | P13: 46036 | Q13: 1 | S13: EJEMPLO | V13: =IF(C13="","",IFERROR(INDEX(Catalogo!$C$5:$C$129,MATCH(C13,Catalogo!$A$5:$A$129,0)),"Código no existe")) | W13: =IF(C13="","",IFERROR(INDEX(Catalogo!$G$5:$G$129,MATCH(C13,Catalogo!$A$5:$A$129,0)),"")) | X13: =IF(C13="","",IF(ISNUMBER(F13),F13,IF(AND(ISNUMBER(D13),ISNUMBER(E13),E13>0),D13/E13*IF(W13="%",100,1),IF(ISNUMBER(D13),D13,"")))) | Y13: =IF(C13="","",IF(A13="","Falta periodo",IF(COUNTIF(Listas!$A$2:$A$134,A13)=0,"Periodo no válido",IF(X13="","Falta valor",IF(I13="","Falta fuente: no se mostrará",IF(AND(J13="",K13=""),"Sin evidencia",IF(N13<>"Validado","Sin validar","OK")))))))
A14: 2023 | C14: ID4 | D14: 154 | E14: 320 | I14: EJEMPLO Encuesta o registro de la escuela, periodo 2023 | L14: EJEMPLO Coord. de calidad de Obstetricia | M14: 45315 | N14: Observado | Q14: 1 | S14: EJEMPLO | V14: =IF(C14="","",IFERROR(INDEX(Catalogo!$C$5:$C$129,MATCH(C14,Catalogo!$A$5:$A$129,0)),"Código no existe")) | W14: =IF(C14="","",IFERROR(INDEX(Catalogo!$G$5:$G$129,MATCH(C14,Catalogo!$A$5:$A$129,0)),"")) | X14: =IF(C14="","",IF(ISNUMBER(F14),F14,IF(AND(ISNUMBER(D14),ISNUMBER(E14),E14>0),D14/E14*IF(W14="%",100,1),IF(ISNUMBER(D14),D14,"")))) | Y14: =IF(C14="","",IF(A14="","Falta periodo",IF(COUNTIF(Listas!$A$2:$A$134,A14)=0,"Periodo no válido",IF(X14="","Falta valor",IF(I14="","Falta fuente: no se mostrará",IF(AND(J14="",K14=""),"Sin evidencia",IF(N14<>"Validado","Sin validar","OK")))))))
A15: 2024 | C15: ID4 | D15: 111 | E15: 210 | I15: EJEMPLO Encuesta o registro de la escuela, periodo 2024 | J15: EV41 | K15: EJEMPLO_ID4_2024.pdf | L15: EJEMPLO Coord. de calidad de Obstetricia | M15: 45663 | N15: Borrador | Q15: 1 | S15: EJEMPLO | V15: =IF(C15="","",IFERROR(INDEX(Catalogo!$C$5:$C$129,MATCH(C15,Catalogo!$A$5:$A$129,0)),"Código no existe")) | W15: =IF(C15="","",IFERROR(INDEX(Catalogo!$G$5:$G$129,MATCH(C15,Catalogo!$A$5:$A$129,0)),"")) | X15: =IF(C15="","",IF(ISNUMBER(F15),F15,IF(AND(ISNUMBER(D15),ISNUMBER(E15),E15>0),D15/E15*IF(W15="%",100,1),IF(ISNUMBER(D15),D15,"")))) | Y15: =IF(C15="","",IF(A15="","Falta periodo",IF(COUNTIF(Listas!$A$2:$A$134,A15)=0,"Periodo no válido",IF(X15="","Falta valor",IF(I15="","Falta fuente: no se mostrará",IF(AND(J15="",K15=""),"Sin evidencia",IF(N15<>"Validado","Sin validar","OK")))))))
A16: 2025 | C16: ID4 | D16: 32 | E16: 60 | I16: EJEMPLO Encuesta o registro de la escuela, periodo 2025 | J16: EV21 | K16: EJEMPLO_ID4_2025.pdf | L16: EJEMPLO Coord. de calidad de Obstetricia | M16: 46050 | N16: Validado | O16: EJEMPLO Dirección de Escuela de Obstetricia | P16: 46058 | Q16: 1 | S16: EJEMPLO | V16: =IF(C16="","",IFERROR(INDEX(Catalogo!$C$5:$C$129,MATCH(C16,Catalogo!$A$5:$A$129,0)),"Código no existe")) | W16: =IF(C16="","",IFERROR(INDEX(Catalogo!$G$5:$G$129,MATCH(C16,Catalogo!$A$5:$A$129,0)),"")) | X16: =IF(C16="","",IF(ISNUMBER(F16),F16,IF(AND(ISNUMBER(D16),ISNUMBER(E16),E16>0),D16/E16*IF(W16="%",100,1),IF(ISNUMBER(D16),D16,"")))) | Y16: =IF(C16="","",IF(A16="","Falta periodo",IF(COUNTIF(Listas!$A$2:$A$134,A16)=0,"Periodo no válido",IF(X16="","Falta valor",IF(I16="","Falta fuente: no se mostrará",IF(AND(J16="",K16=""),"Sin evidencia",IF(N16<>"Validado","Sin validar","OK")))))))
A17: 2024-S2 | C17: ID5 | D17: 224 | E17: 320 | I17: EJEMPLO Encuesta o registro de la escuela, periodo 2024-S2 | J17: EV38 | K17: EJEMPLO_ID5_2024-S2.pdf | L17: EJEMPLO Coord. de calidad de Obstetricia | M17: 45674 | N17: Validado | O17: EJEMPLO Dirección de Escuela de Obstetricia | P17: 45677 | Q17: 1 | S17: EJEMPLO | V17: =IF(C17="","",IFERROR(INDEX(Catalogo!$C$5:$C$129,MATCH(C17,Catalogo!$A$5:$A$129,0)),"Código no existe")) | W17: =IF(C17="","",IFERROR(INDEX(Catalogo!$G$5:$G$129,MATCH(C17,Catalogo!$A$5:$A$129,0)),"")) | X17: =IF(C17="","",IF(ISNUMBER(F17),F17,IF(AND(ISNUMBER(D17),ISNUMBER(E17),E17>0),D17/E17*IF(W17="%",100,1),IF(ISNUMBER(D17),D17,"")))) | Y17: =IF(C17="","",IF(A17="","Falta periodo",IF(COUNTIF(Listas!$A$2:$A$134,A17)=0,"Periodo no válido",IF(X17="","Falta valor",IF(I17="","Falta fuente: no se mostrará",IF(AND(J17="",K17=""),"Sin evidencia",IF(N17<>"Validado","Sin validar","OK")))))))
A18: 2025-S1 | C18: ID5 | D18: 88 | E18: 120 | I18: EJEMPLO Encuesta o registro de la escuela, periodo 2025-S1 | J18: EV38 | K18: EJEMPLO_ID5_2025-S1.pdf | L18: EJEMPLO Coord. de calidad de Obstetricia | M18: 45850 | N18: Validado | O18: EJEMPLO Dirección de Escuela de Obstetricia | P18: 45854 | Q18: 1 | S18: EJEMPLO | V18: =IF(C18="","",IFERROR(INDEX(Catalogo!$C$5:$C$129,MATCH(C18,Catalogo!$A$5:$A$129,0)),"Código no existe")) | W18: =IF(C18="","",IFERROR(INDEX(Catalogo!$G$5:$G$129,MATCH(C18,Catalogo!$A$5:$A$129,0)),"")) | X18: =IF(C18="","",IF(ISNUMBER(F18),F18,IF(AND(ISNUMBER(D18),ISNUMBER(E18),E18>0),D18/E18*IF(W18="%",100,1),IF(ISNUMBER(D18),D18,"")))) | Y18: =IF(C18="","",IF(A18="","Falta periodo",IF(COUNTIF(Listas!$A$2:$A$134,A18)=0,"Periodo no válido",IF(X18="","Falta valor",IF(I18="","Falta fuente: no se mostrará",IF(AND(J18="",K18=""),"Sin evidencia",IF(N18<>"Validado","Sin validar","OK")))))))
A19: 2025-S2 | C19: ID5 | D19: 107 | E19: 150 | I19: EJEMPLO Encuesta o registro de la escuela, periodo 2025-S2 | J19: EV21 | K19: EJEMPLO_ID5_2025-S2.pdf | L19: EJEMPLO Coord. de calidad de Obstetricia | M19: 46034 | N19: Borrador | Q19: 1 | S19: EJEMPLO | V19: =IF(C19="","",IFERROR(INDEX(Catalogo!$C$5:$C$129,MATCH(C19,Catalogo!$A$5:$A$129,0)),"Código no existe")) | W19: =IF(C19="","",IFERROR(INDEX(Catalogo!$G$5:$G$129,MATCH(C19,Catalogo!$A$5:$A$129,0)),"")) | X19: =IF(C19="","",IF(ISNUMBER(F19),F19,IF(AND(ISNUMBER(D19),ISNUMBER(E19),E19>0),D19/E19*IF(W19="%",100,1),IF(ISNUMBER(D19),D19,"")))) | Y19: =IF(C19="","",IF(A19="","Falta periodo",IF(COUNTIF(Listas!$A$2:$A$134,A19)=0,"Periodo no válido",IF(X19="","Falta valor",IF(I19="","Falta fuente: no se mostrará",IF(AND(J19="",K19=""),"Sin evidencia",IF(N19<>"Validado","Sin validar","OK")))))))
A20: 2023 | C20: ID6 | D20: 3 | E20: 320 | I20: EJEMPLO Encuesta o registro de la escuela, periodo 2023 | J20: EV44 | K20: EJEMPLO_ID6_2023.pdf | L20: EJEMPLO Coord. de calidad de Obstetricia | M20: 45298 | N20: Validado | O20: EJEMPLO Dirección de Escuela de Obstetricia | P20: 45303 | Q20: 1 | S20: EJEMPLO | V20: =IF(C20="","",IFERROR(INDEX(Catalogo!$C$5:$C$129,MATCH(C20,Catalogo!$A$5:$A$129,0)),"Código no existe")) | W20: =IF(C20="","",IFERROR(INDEX(Catalogo!$G$5:$G$129,MATCH(C20,Catalogo!$A$5:$A$129,0)),"")) | X20: =IF(C20="","",IF(ISNUMBER(F20),F20,IF(AND(ISNUMBER(D20),ISNUMBER(E20),E20>0),D20/E20*IF(W20="%",100,1),IF(ISNUMBER(D20),D20,"")))) | Y20: =IF(C20="","",IF(A20="","Falta periodo",IF(COUNTIF(Listas!$A$2:$A$134,A20)=0,"Periodo no válido",IF(X20="","Falta valor",IF(I20="","Falta fuente: no se mostrará",IF(AND(J20="",K20=""),"Sin evidencia",IF(N20<>"Validado","Sin validar","OK")))))))
A21: 2024 | C21: ID6 | D21: 1 | E21: 60 | I21: EJEMPLO Encuesta o registro de la escuela, periodo 2024 | J21: EV21 | K21: EJEMPLO_ID6_2024.pdf | L21: EJEMPLO Coord. de calidad de Obstetricia | M21: 45679 | N21: Validado | O21: EJEMPLO Dirección de Escuela de Obstetricia | P21: 45681 | Q21: 1 | S21: EJEMPLO | V21: =IF(C21="","",IFERROR(INDEX(Catalogo!$C$5:$C$129,MATCH(C21,Catalogo!$A$5:$A$129,0)),"Código no existe")) | W21: =IF(C21="","",IFERROR(INDEX(Catalogo!$G$5:$G$129,MATCH(C21,Catalogo!$A$5:$A$129,0)),"")) | X21: =IF(C21="","",IF(ISNUMBER(F21),F21,IF(AND(ISNUMBER(D21),ISNUMBER(E21),E21>0),D21/E21*IF(W21="%",100,1),IF(ISNUMBER(D21),D21,"")))) | Y21: =IF(C21="","",IF(A21="","Falta periodo",IF(COUNTIF(Listas!$A$2:$A$134,A21)=0,"Periodo no válido",IF(X21="","Falta valor",IF(I21="","Falta fuente: no se mostrará",IF(AND(J21="",K21=""),"Sin evidencia",IF(N21<>"Validado","Sin validar","OK")))))))
A22: 2025 | C22: ID6 | D22: 2 | E22: 210 | I22: EJEMPLO Encuesta o registro de la escuela, periodo 2025 | J22: EV38 | K22: EJEMPLO_ID6_2025.pdf | L22: EJEMPLO Coord. de calidad de Obstetricia | M22: 46047 | N22: Validado | O22: EJEMPLO Dirección de Escuela de Obstetricia | P22: 46048 | Q22: 1 | S22: EJEMPLO | V22: =IF(C22="","",IFERROR(INDEX(Catalogo!$C$5:$C$129,MATCH(C22,Catalogo!$A$5:$A$129,0)),"Código no existe")) | W22: =IF(C22="","",IFERROR(INDEX(Catalogo!$G$5:$G$129,MATCH(C22,Catalogo!$A$5:$A$129,0)),"")) | X22: =IF(C22="","",IF(ISNUMBER(F22),F22,IF(AND(ISNUMBER(D22),ISNUMBER(E22),E22>0),D22/E22*IF(W22="%",100,1),IF(ISNUMBER(D22),D22,"")))) | Y22: =IF(C22="","",IF(A22="","Falta periodo",IF(COUNTIF(Listas!$A$2:$A$134,A22)=0,"Periodo no válido",IF(X22="","Falta valor",IF(I22="","Falta fuente: no se mostrará",IF(AND(J22="",K22=""),"Sin evidencia",IF(N22<>"Validado","Sin validar","OK")))))))
A23: 2023 | C23: ID7 | D23: 96 | E23: 210 | I23: EJEMPLO Encuesta o registro de la escuela, periodo 2023 | J23: EV38 | K23: EJEMPLO_ID7_2023.pdf | L23: EJEMPLO Coord. de calidad de Obstetricia | M23: 45308 | N23: Validado | O23: EJEMPLO Dirección de Escuela de Obstetricia | P23: 45310 | Q23: 1 | S23: EJEMPLO | V23: =IF(C23="","",IFERROR(INDEX(Catalogo!$C$5:$C$129,MATCH(C23,Catalogo!$A$5:$A$129,0)),"Código no existe")) | W23: =IF(C23="","",IFERROR(INDEX(Catalogo!$G$5:$G$129,MATCH(C23,Catalogo!$A$5:$A$129,0)),"")) | X23: =IF(C23="","",IF(ISNUMBER(F23),F23,IF(AND(ISNUMBER(D23),ISNUMBER(E23),E23>0),D23/E23*IF(W23="%",100,1),IF(ISNUMBER(D23),D23,"")))) | Y23: =IF(C23="","",IF(A23="","Falta periodo",IF(COUNTIF(Listas!$A$2:$A$134,A23)=0,"Periodo no válido",IF(X23="","Falta valor",IF(I23="","Falta fuente: no se mostrará",IF(AND(J23="",K23=""),"Sin evidencia",IF(N23<>"Validado","Sin validar","OK")))))))
A24: 2024 | C24: ID7 | D24: 38 | E24: 85 | I24: EJEMPLO Encuesta o registro de la escuela, periodo 2024 | J24: EV13 | K24: EJEMPLO_ID7_2024.pdf | L24: EJEMPLO Coord. de calidad de Obstetricia | M24: 45668 | N24: Observado | Q24: 1 | S24: EJEMPLO | V24: =IF(C24="","",IFERROR(INDEX(Catalogo!$C$5:$C$129,MATCH(C24,Catalogo!$A$5:$A$129,0)),"Código no existe")) | W24: =IF(C24="","",IFERROR(INDEX(Catalogo!$G$5:$G$129,MATCH(C24,Catalogo!$A$5:$A$129,0)),"")) | X24: =IF(C24="","",IF(ISNUMBER(F24),F24,IF(AND(ISNUMBER(D24),ISNUMBER(E24),E24>0),D24/E24*IF(W24="%",100,1),IF(ISNUMBER(D24),D24,"")))) | Y24: =IF(C24="","",IF(A24="","Falta periodo",IF(COUNTIF(Listas!$A$2:$A$134,A24)=0,"Periodo no válido",IF(X24="","Falta valor",IF(I24="","Falta fuente: no se mostrará",IF(AND(J24="",K24=""),"Sin evidencia",IF(N24<>"Validado","Sin validar","OK")))))))
A25: 2025 | C25: ID7 | D25: 94 | E25: 210 | I25: EJEMPLO Encuesta o registro de la escuela, periodo 2025 | J25: EV30 | K25: EJEMPLO_ID7_2025.pdf | L25: EJEMPLO Coord. de calidad de Obstetricia | M25: 46036 | N25: Validado | O25: EJEMPLO Dirección de Escuela de Obstetricia | P25: 46040 | Q25: 1 | S25: EJEMPLO | V25: =IF(C25="","",IFERROR(INDEX(Catalogo!$C$5:$C$129,MATCH(C25,Catalogo!$A$5:$A$129,0)),"Código no existe")) | W25: =IF(C25="","",IFERROR(INDEX(Catalogo!$G$5:$G$129,MATCH(C25,Catalogo!$A$5:$A$129,0)),"")) | X25: =IF(C25="","",IF(ISNUMBER(F25),F25,IF(AND(ISNUMBER(D25),ISNUMBER(E25),E25>0),D25/E25*IF(W25="%",100,1),IF(ISNUMBER(D25),D25,"")))) | Y25: =IF(C25="","",IF(A25="","Falta periodo",IF(COUNTIF(Listas!$A$2:$A$134,A25)=0,"Periodo no válido",IF(X25="","Falta valor",IF(I25="","Falta fuente: no se mostrará",IF(AND(J25="",K25=""),"Sin evidencia",IF(N25<>"Validado","Sin validar","OK")))))))
A26: 2024-S2 | C26: ID10 | D26: 31 | E26: 48 | I26: EJEMPLO Encuesta o registro de la escuela, periodo 2024-S2 | J26: EV21 | K26: EJEMPLO_ID10_2024-S2.pdf | L26: EJEMPLO Coord. de calidad de Obstetricia | M26: 45674 | N26: Validado | O26: EJEMPLO Dirección de Escuela de Obstetricia | P26: 45678 | Q26: 1 | S26: EJEMPLO | V26: =IF(C26="","",IFERROR(INDEX(Catalogo!$C$5:$C$129,MATCH(C26,Catalogo!$A$5:$A$129,0)),"Código no existe")) | W26: =IF(C26="","",IFERROR(INDEX(Catalogo!$G$5:$G$129,MATCH(C26,Catalogo!$A$5:$A$129,0)),"")) | X26: =IF(C26="","",IF(ISNUMBER(F26),F26,IF(AND(ISNUMBER(D26),ISNUMBER(E26),E26>0),D26/E26*IF(W26="%",100,1),IF(ISNUMBER(D26),D26,"")))) | Y26: =IF(C26="","",IF(A26="","Falta periodo",IF(COUNTIF(Listas!$A$2:$A$134,A26)=0,"Periodo no válido",IF(X26="","Falta valor",IF(I26="","Falta fuente: no se mostrará",IF(AND(J26="",K26=""),"Sin evidencia",IF(N26<>"Validado","Sin validar","OK")))))))
A27: 2025-S1 | C27: ID10 | D27: 60 | E27: 85 | I27: EJEMPLO Encuesta o registro de la escuela, periodo 2025-S1 | J27: EV44 | K27: EJEMPLO_ID10_2025-S1.pdf | L27: EJEMPLO Coord. de calidad de Obstetricia | M27: 45856 | N27: Validado | O27: EJEMPLO Dirección de Escuela de Obstetricia | P27: 45861 | Q27: 1 | S27: EJEMPLO | V27: =IF(C27="","",IFERROR(INDEX(Catalogo!$C$5:$C$129,MATCH(C27,Catalogo!$A$5:$A$129,0)),"Código no existe")) | W27: =IF(C27="","",IFERROR(INDEX(Catalogo!$G$5:$G$129,MATCH(C27,Catalogo!$A$5:$A$129,0)),"")) | X27: =IF(C27="","",IF(ISNUMBER(F27),F27,IF(AND(ISNUMBER(D27),ISNUMBER(E27),E27>0),D27/E27*IF(W27="%",100,1),IF(ISNUMBER(D27),D27,"")))) | Y27: =IF(C27="","",IF(A27="","Falta periodo",IF(COUNTIF(Listas!$A$2:$A$134,A27)=0,"Periodo no válido",IF(X27="","Falta valor",IF(I27="","Falta fuente: no se mostrará",IF(AND(J27="",K27=""),"Sin evidencia",IF(N27<>"Validado","Sin validar","OK")))))))
A28: 2025-S2 | C28: ID10 | D28: 32 | E28: 48 | I28: EJEMPLO Encuesta o registro de la escuela, periodo 2025-S2 | L28: EJEMPLO Coord. de calidad de Obstetricia | M28: 46046 | N28: Validado | O28: EJEMPLO Dirección de Escuela de Obstetricia | P28: 46047 | Q28: 1 | S28: EJEMPLO | V28: =IF(C28="","",IFERROR(INDEX(Catalogo!$C$5:$C$129,MATCH(C28,Catalogo!$A$5:$A$129,0)),"Código no existe")) | W28: =IF(C28="","",IFERROR(INDEX(Catalogo!$G$5:$G$129,MATCH(C28,Catalogo!$A$5:$A$129,0)),"")) | X28: =IF(C28="","",IF(ISNUMBER(F28),F28,IF(AND(ISNUMBER(D28),ISNUMBER(E28),E28>0),D28/E28*IF(W28="%",100,1),IF(ISNUMBER(D28),D28,"")))) | Y28: =IF(C28="","",IF(A28="","Falta periodo",IF(COUNTIF(Listas!$A$2:$A$134,A28)=0,"Periodo no válido",IF(X28="","Falta valor",IF(I28="","Falta fuente: no se mostrará",IF(AND(J28="",K28=""),"Sin evidencia",IF(N28<>"Validado","Sin validar","OK")))))))
A29: 2026-S1 | C29: ID10 | D29: 211 | E29: 320 | I29: EJEMPLO Encuesta o registro de la escuela, periodo 2026-S1 | J29: EV43 | K29: EJEMPLO_ID10_2026-S1.pdf | L29: EJEMPLO Coord. de calidad de Obstetricia | M29: 46223 | N29: Borrador | Q29: 1 | S29: EJEMPLO | V29: =IF(C29="","",IFERROR(INDEX(Catalogo!$C$5:$C$129,MATCH(C29,Catalogo!$A$5:$A$129,0)),"Código no existe")) | W29: =IF(C29="","",IFERROR(INDEX(Catalogo!$G$5:$G$129,MATCH(C29,Catalogo!$A$5:$A$129,0)),"")) | X29: =IF(C29="","",IF(ISNUMBER(F29),F29,IF(AND(ISNUMBER(D29),ISNUMBER(E29),E29>0),D29/E29*IF(W29="%",100,1),IF(ISNUMBER(D29),D29,"")))) | Y29: =IF(C29="","",IF(A29="","Falta periodo",IF(COUNTIF(Listas!$A$2:$A$134,A29)=0,"Periodo no válido",IF(X29="","Falta valor",IF(I29="","Falta fuente: no se mostrará",IF(AND(J29="",K29=""),"Sin evidencia",IF(N29<>"Validado","Sin validar","OK")))))))
A30: 2025-S1 | C30: ID11 | D30: 257 | E30: 320 | I30: EJEMPLO Encuesta o registro de la escuela, periodo 2025-S1 | J30: EV21 | K30: EJEMPLO_ID11_2025-S1.pdf | L30: EJEMPLO Coord. de calidad de Obstetricia | M30: 45845 | N30: Validado | O30: EJEMPLO Dirección de Escuela de Obstetricia | P30: 45847 | Q30: 1 | S30: EJEMPLO | V30: =IF(C30="","",IFERROR(INDEX(Catalogo!$C$5:$C$129,MATCH(C30,Catalogo!$A$5:$A$129,0)),"Código no existe")) | W30: =IF(C30="","",IFERROR(INDEX(Catalogo!$G$5:$G$129,MATCH(C30,Catalogo!$A$5:$A$129,0)),"")) | X30: =IF(C30="","",IF(ISNUMBER(F30),F30,IF(AND(ISNUMBER(D30),ISNUMBER(E30),E30>0),D30/E30*IF(W30="%",100,1),IF(ISNUMBER(D30),D30,"")))) | Y30: =IF(C30="","",IF(A30="","Falta periodo",IF(COUNTIF(Listas!$A$2:$A$134,A30)=0,"Periodo no válido",IF(X30="","Falta valor",IF(I30="","Falta fuente: no se mostrará",IF(AND(J30="",K30=""),"Sin evidencia",IF(N30<>"Validado","Sin validar","OK")))))))
A31: 2025-S2 | C31: ID11 | D31: 109 | E31: 150 | I31: EJEMPLO Encuesta o registro de la escuela, periodo 2025-S2 | J31: EV35 | K31: EJEMPLO_ID11_2025-S2.pdf | L31: EJEMPLO Coord. de calidad de Obstetricia | M31: 46048 | N31: Observado | Q31: 1 | S31: EJEMPLO | V31: =IF(C31="","",IFERROR(INDEX(Catalogo!$C$5:$C$129,MATCH(C31,Catalogo!$A$5:$A$129,0)),"Código no existe")) | W31: =IF(C31="","",IFERROR(INDEX(Catalogo!$G$5:$G$129,MATCH(C31,Catalogo!$A$5:$A$129,0)),"")) | X31: =IF(C31="","",IF(ISNUMBER(F31),F31,IF(AND(ISNUMBER(D31),ISNUMBER(E31),E31>0),D31/E31*IF(W31="%",100,1),IF(ISNUMBER(D31),D31,"")))) | Y31: =IF(C31="","",IF(A31="","Falta periodo",IF(COUNTIF(Listas!$A$2:$A$134,A31)=0,"Periodo no válido",IF(X31="","Falta valor",IF(I31="","Falta fuente: no se mostrará",IF(AND(J31="",K31=""),"Sin evidencia",IF(N31<>"Validado","Sin validar","OK")))))))
A32: 2026-S1 | C32: ID11 | D32: 159 | E32: 210 | I32: EJEMPLO Encuesta o registro de la escuela, periodo 2026-S1 | J32: EV44 | K32: EJEMPLO_ID11_2026-S1.pdf | L32: EJEMPLO Coord. de calidad de Obstetricia | M32: 46215 | N32: Validado | O32: EJEMPLO Dirección de Escuela de Obstetricia | P32: 46219 | Q32: 1 | S32: EJEMPLO | V32: =IF(C32="","",IFERROR(INDEX(Catalogo!$C$5:$C$129,MATCH(C32,Catalogo!$A$5:$A$129,0)),"Código no existe")) | W32: =IF(C32="","",IFERROR(INDEX(Catalogo!$G$5:$G$129,MATCH(C32,Catalogo!$A$5:$A$129,0)),"")) | X32: =IF(C32="","",IF(ISNUMBER(F32),F32,IF(AND(ISNUMBER(D32),ISNUMBER(E32),E32>0),D32/E32*IF(W32="%",100,1),IF(ISNUMBER(D32),D32,"")))) | Y32: =IF(C32="","",IF(A32="","Falta periodo",IF(COUNTIF(Listas!$A$2:$A$134,A32)=0,"Periodo no válido",IF(X32="","Falta valor",IF(I32="","Falta fuente: no se mostrará",IF(AND(J32="",K32=""),"Sin evidencia",IF(N32<>"Validado","Sin validar","OK")))))))
A33: 2024 | C33: ID12 | D33: 60 | E33: 120 | I33: EJEMPLO Encuesta o registro de la escuela, periodo 2024 | J33: EV43 | K33: EJEMPLO_ID12_2024.pdf | L33: EJEMPLO Coord. de calidad de Obstetricia | M33: 45668 | N33: Validado | O33: EJEMPLO Dirección de Escuela de Obstetricia | P33: 45669 | Q33: 1 | S33: EJEMPLO | V33: =IF(C33="","",IFERROR(INDEX(Catalogo!$C$5:$C$129,MATCH(C33,Catalogo!$A$5:$A$129,0)),"Código no existe")) | W33: =IF(C33="","",IFERROR(INDEX(Catalogo!$G$5:$G$129,MATCH(C33,Catalogo!$A$5:$A$129,0)),"")) | X33: =IF(C33="","",IF(ISNUMBER(F33),F33,IF(AND(ISNUMBER(D33),ISNUMBER(E33),E33>0),D33/E33*IF(W33="%",100,1),IF(ISNUMBER(D33),D33,"")))) | Y33: =IF(C33="","",IF(A33="","Falta periodo",IF(COUNTIF(Listas!$A$2:$A$134,A33)=0,"Periodo no válido",IF(X33="","Falta valor",IF(I33="","Falta fuente: no se mostrará",IF(AND(J33="",K33=""),"Sin evidencia",IF(N33<>"Validado","Sin validar","OK")))))))
A34: 2025 | C34: ID12 | D34: 75 | E34: 150 | I34: EJEMPLO Encuesta o registro de la escuela, periodo 2025 | J34: EV30 | K34: EJEMPLO_ID12_2025.pdf | L34: EJEMPLO Coord. de calidad de Obstetricia | M34: 46041 | N34: Borrador | Q34: 1 | S34: EJEMPLO | V34: =IF(C34="","",IFERROR(INDEX(Catalogo!$C$5:$C$129,MATCH(C34,Catalogo!$A$5:$A$129,0)),"Código no existe")) | W34: =IF(C34="","",IFERROR(INDEX(Catalogo!$G$5:$G$129,MATCH(C34,Catalogo!$A$5:$A$129,0)),"")) | X34: =IF(C34="","",IF(ISNUMBER(F34),F34,IF(AND(ISNUMBER(D34),ISNUMBER(E34),E34>0),D34/E34*IF(W34="%",100,1),IF(ISNUMBER(D34),D34,"")))) | Y34: =IF(C34="","",IF(A34="","Falta periodo",IF(COUNTIF(Listas!$A$2:$A$134,A34)=0,"Periodo no válido",IF(X34="","Falta valor",IF(I34="","Falta fuente: no se mostrará",IF(AND(J34="",K34=""),"Sin evidencia",IF(N34<>"Validado","Sin validar","OK")))))))
A35: 2023 | C35: ID13 | D35: 8 | E35: 120 | I35: EJEMPLO Encuesta o registro de la escuela, periodo 2023 | L35: EJEMPLO Coord. de calidad de Obstetricia | M35: 45313 | N35: Validado | O35: EJEMPLO Dirección de Escuela de Obstetricia | P35: 45318 | Q35: 1 | S35: EJEMPLO | V35: =IF(C35="","",IFERROR(INDEX(Catalogo!$C$5:$C$129,MATCH(C35,Catalogo!$A$5:$A$129,0)),"Código no existe")) | W35: =IF(C35="","",IFERROR(INDEX(Catalogo!$G$5:$G$129,MATCH(C35,Catalogo!$A$5:$A$129,0)),"")) | X35: =IF(C35="","",IF(ISNUMBER(F35),F35,IF(AND(ISNUMBER(D35),ISNUMBER(E35),E35>0),D35/E35*IF(W35="%",100,1),IF(ISNUMBER(D35),D35,"")))) | Y35: =IF(C35="","",IF(A35="","Falta periodo",IF(COUNTIF(Listas!$A$2:$A$134,A35)=0,"Periodo no válido",IF(X35="","Falta valor",IF(I35="","Falta fuente: no se mostrará",IF(AND(J35="",K35=""),"Sin evidencia",IF(N35<>"Validado","Sin validar","OK")))))))
A36: 2024 | C36: ID13 | D36: 15 | E36: 210 | I36: EJEMPLO Encuesta o registro de la escuela, periodo 2024 | L36: EJEMPLO Coord. de calidad de Obstetricia | M36: 45670 | N36: Validado | O36: EJEMPLO Dirección de Escuela de Obstetricia | P36: 45677 | Q36: 1 | S36: EJEMPLO | V36: =IF(C36="","",IFERROR(INDEX(Catalogo!$C$5:$C$129,MATCH(C36,Catalogo!$A$5:$A$129,0)),"Código no existe")) | W36: =IF(C36="","",IFERROR(INDEX(Catalogo!$G$5:$G$129,MATCH(C36,Catalogo!$A$5:$A$129,0)),"")) | X36: =IF(C36="","",IF(ISNUMBER(F36),F36,IF(AND(ISNUMBER(D36),ISNUMBER(E36),E36>0),D36/E36*IF(W36="%",100,1),IF(ISNUMBER(D36),D36,"")))) | Y36: =IF(C36="","",IF(A36="","Falta periodo",IF(COUNTIF(Listas!$A$2:$A$134,A36)=0,"Periodo no válido",IF(X36="","Falta valor",IF(I36="","Falta fuente: no se mostrará",IF(AND(J36="",K36=""),"Sin evidencia",IF(N36<>"Validado","Sin validar","OK")))))))
A37: 2025 | C37: ID13 | D37: 24 | E37: 320 | I37: EJEMPLO Encuesta o registro de la escuela, periodo 2025 | J37: EV35 | K37: EJEMPLO_ID13_2025.pdf | L37: EJEMPLO Coord. de calidad de Obstetricia | M37: 46030 | N37: Validado | O37: EJEMPLO Dirección de Escuela de Obstetricia | P37: 46032 | Q37: 1 | S37: EJEMPLO | V37: =IF(C37="","",IFERROR(INDEX(Catalogo!$C$5:$C$129,MATCH(C37,Catalogo!$A$5:$A$129,0)),"Código no existe")) | W37: =IF(C37="","",IFERROR(INDEX(Catalogo!$G$5:$G$129,MATCH(C37,Catalogo!$A$5:$A$129,0)),"")) | X37: =IF(C37="","",IF(ISNUMBER(F37),F37,IF(AND(ISNUMBER(D37),ISNUMBER(E37),E37>0),D37/E37*IF(W37="%",100,1),IF(ISNUMBER(D37),D37,"")))) | Y37: =IF(C37="","",IF(A37="","Falta periodo",IF(COUNTIF(Listas!$A$2:$A$134,A37)=0,"Periodo no válido",IF(X37="","Falta valor",IF(I37="","Falta fuente: no se mostrará",IF(AND(J37="",K37=""),"Sin evidencia",IF(N37<>"Validado","Sin validar","OK")))))))
A38: 2023 | C38: ID14 | D38: 48 | E38: 210 | I38: EJEMPLO Encuesta o registro de la escuela, periodo 2023 | J38: EV13 | K38: EJEMPLO_ID14_2023.pdf | L38: EJEMPLO Coord. de calidad de Obstetricia | M38: 45300 | N38: Validado | O38: EJEMPLO Dirección de Escuela de Obstetricia | P38: 45305 | Q38: 1 | S38: EJEMPLO | V38: =IF(C38="","",IFERROR(INDEX(Catalogo!$C$5:$C$129,MATCH(C38,Catalogo!$A$5:$A$129,0)),"Código no existe")) | W38: =IF(C38="","",IFERROR(INDEX(Catalogo!$G$5:$G$129,MATCH(C38,Catalogo!$A$5:$A$129,0)),"")) | X38: =IF(C38="","",IF(ISNUMBER(F38),F38,IF(AND(ISNUMBER(D38),ISNUMBER(E38),E38>0),D38/E38*IF(W38="%",100,1),IF(ISNUMBER(D38),D38,"")))) | Y38: =IF(C38="","",IF(A38="","Falta periodo",IF(COUNTIF(Listas!$A$2:$A$134,A38)=0,"Periodo no válido",IF(X38="","Falta valor",IF(I38="","Falta fuente: no se mostrará",IF(AND(J38="",K38=""),"Sin evidencia",IF(N38<>"Validado","Sin validar","OK")))))))
A39: 2024 | C39: ID14 | D39: 11 | E39: 48 | I39: EJEMPLO Encuesta o registro de la escuela, periodo 2024 | J39: EV35 | K39: EJEMPLO_ID14_2024.pdf | L39: EJEMPLO Coord. de calidad de Obstetricia | M39: 45675 | N39: Validado | O39: EJEMPLO Dirección de Escuela de Obstetricia | P39: 45678 | Q39: 1 | S39: EJEMPLO | V39: =IF(C39="","",IFERROR(INDEX(Catalogo!$C$5:$C$129,MATCH(C39,Catalogo!$A$5:$A$129,0)),"Código no existe")) | W39: =IF(C39="","",IFERROR(INDEX(Catalogo!$G$5:$G$129,MATCH(C39,Catalogo!$A$5:$A$129,0)),"")) | X39: =IF(C39="","",IF(ISNUMBER(F39),F39,IF(AND(ISNUMBER(D39),ISNUMBER(E39),E39>0),D39/E39*IF(W39="%",100,1),IF(ISNUMBER(D39),D39,"")))) | Y39: =IF(C39="","",IF(A39="","Falta periodo",IF(COUNTIF(Listas!$A$2:$A$134,A39)=0,"Periodo no válido",IF(X39="","Falta valor",IF(I39="","Falta fuente: no se mostrará",IF(AND(J39="",K39=""),"Sin evidencia",IF(N39<>"Validado","Sin validar","OK")))))))
A40: 2025 | C40: ID14 | D40: 18 | E40: 85 | I40: EJEMPLO Encuesta o registro de la escuela, periodo 2025 | J40: EV21 | K40: EJEMPLO_ID14_2025.pdf | L40: EJEMPLO Coord. de calidad de Obstetricia | M40: 46029 | N40: Validado | O40: EJEMPLO Dirección de Escuela de Obstetricia | P40: 46030 | Q40: 1 | S40: EJEMPLO | V40: =IF(C40="","",IFERROR(INDEX(Catalogo!$C$5:$C$129,MATCH(C40,Catalogo!$A$5:$A$129,0)),"Código no existe")) | W40: =IF(C40="","",IFERROR(INDEX(Catalogo!$G$5:$G$129,MATCH(C40,Catalogo!$A$5:$A$129,0)),"")) | X40: =IF(C40="","",IF(ISNUMBER(F40),F40,IF(AND(ISNUMBER(D40),ISNUMBER(E40),E40>0),D40/E40*IF(W40="%",100,1),IF(ISNUMBER(D40),D40,"")))) | Y40: =IF(C40="","",IF(A40="","Falta periodo",IF(COUNTIF(Listas!$A$2:$A$134,A40)=0,"Periodo no válido",IF(X40="","Falta valor",IF(I40="","Falta fuente: no se mostrará",IF(AND(J40="",K40=""),"Sin evidencia",IF(N40<>"Validado","Sin validar","OK")))))))
A41: 2023 | C41: ID16 | D41: 32 | E41: 60 | I41: EJEMPLO Encuesta o registro de la escuela, periodo 2023 | J41: EV42 | K41: EJEMPLO_ID16_2023.pdf | L41: EJEMPLO Coord. de calidad de Obstetricia | M41: 45319 | N41: Validado | O41: EJEMPLO Dirección de Escuela de Obstetricia | P41: 45327 | Q41: 1 | S41: EJEMPLO | V41: =IF(C41="","",IFERROR(INDEX(Catalogo!$C$5:$C$129,MATCH(C41,Catalogo!$A$5:$A$129,0)),"Código no existe")) | W41: =IF(C41="","",IFERROR(INDEX(Catalogo!$G$5:$G$129,MATCH(C41,Catalogo!$A$5:$A$129,0)),"")) | X41: =IF(C41="","",IF(ISNUMBER(F41),F41,IF(AND(ISNUMBER(D41),ISNUMBER(E41),E41>0),D41/E41*IF(W41="%",100,1),IF(ISNUMBER(D41),D41,"")))) | Y41: =IF(C41="","",IF(A41="","Falta periodo",IF(COUNTIF(Listas!$A$2:$A$134,A41)=0,"Periodo no válido",IF(X41="","Falta valor",IF(I41="","Falta fuente: no se mostrará",IF(AND(J41="",K41=""),"Sin evidencia",IF(N41<>"Validado","Sin validar","OK")))))))
...

Sheet Evidencias
A1: Evidencias del modelo CONEAU por área
A2: EV1 a EV52. Tecnología Médica: una fila por evidencia y por área (Radiología, Terapia Física, Terapia Ocupacional, Laboratorio Clínico y Anatomía Patológica). Enfermería y Obstetricia: área vacía.
A4: ev_id | B4: area_id | C4: estado | D4: ubicacion | E4: responsable | F4: fecha_actualizacion | G4: observacion | H4: origen | I4: estandar | J4: descripcion (paráfrasis)
A5: EV1 | C5: Disponible | D5: EJEMPLO_EV1.pdf | E5: EJEMPLO Coord. de calidad de Obstetricia | F5: 46280 | H5: EJEMPLO | I5: =IF(A5="","",IFERROR(INDEX(CONEAU_EV_EST,MATCH(A5,CONEAU_EV_ID,0)),"")) | J5: =IF(A5="","",IFERROR(INDEX(CONEAU_EV_DESC,MATCH(A5,CONEAU_EV_ID,0)),""))
A6: EV2 | C6: En elaboración | D6: EJEMPLO_EV2.pdf | E6: EJEMPLO Coord. de calidad de Obstetricia | F6: 46280 | H6: EJEMPLO | I6: =IF(A6="","",IFERROR(INDEX(CONEAU_EV_EST,MATCH(A6,CONEAU_EV_ID,0)),"")) | J6: =IF(A6="","",IFERROR(INDEX(CONEAU_EV_DESC,MATCH(A6,CONEAU_EV_ID,0)),""))
A7: EV3 | C7: Validada | D7: EJEMPLO_EV3.pdf | E7: EJEMPLO Coord. de calidad de Obstetricia | F7: 46280 | H7: EJEMPLO | I7: =IF(A7="","",IFERROR(INDEX(CONEAU_EV_EST,MATCH(A7,CONEAU_EV_ID,0)),"")) | J7: =IF(A7="","",IFERROR(INDEX(CONEAU_EV_DESC,MATCH(A7,CONEAU_EV_ID,0)),""))
A8: EV4 | C8: Validada | D8: EJEMPLO_EV4.pdf | E8: EJEMPLO Coord. de calidad de Obstetricia | F8: 46280 | H8: EJEMPLO | I8: =IF(A8="","",IFERROR(INDEX(CONEAU_EV_EST,MATCH(A8,CONEAU_EV_ID,0)),"")) | J8: =IF(A8="","",IFERROR(INDEX(CONEAU_EV_DESC,MATCH(A8,CONEAU_EV_ID,0)),""))
A9: EV5 | C9: Disponible | D9: EJEMPLO_EV5.pdf | E9: EJEMPLO Coord. de calidad de Obstetricia | F9: 46280 | H9: EJEMPLO | I9: =IF(A9="","",IFERROR(INDEX(CONEAU_EV_EST,MATCH(A9,CONEAU_EV_ID,0)),"")) | J9: =IF(A9="","",IFERROR(INDEX(CONEAU_EV_DESC,MATCH(A9,CONEAU_EV_ID,0)),""))
A10: EV6 | C10: En elaboración | D10: EJEMPLO_EV6.pdf | E10: EJEMPLO Coord. de calidad de Obstetricia | F10: 46280 | H10: EJEMPLO | I10: =IF(A10="","",IFERROR(INDEX(CONEAU_EV_EST,MATCH(A10,CONEAU_EV_ID,0)),"")) | J10: =IF(A10="","",IFERROR(INDEX(CONEAU_EV_DESC,MATCH(A10,CONEAU_EV_ID,0)),""))
A11: EV7 | C11: No iniciada | E11: EJEMPLO Coord. de calidad de Obstetricia | H11: EJEMPLO | I11: =IF(A11="","",IFERROR(INDEX(CONEAU_EV_EST,MATCH(A11,CONEAU_EV_ID,0)),"")) | J11: =IF(A11="","",IFERROR(INDEX(CONEAU_EV_DESC,MATCH(A11,CONEAU_EV_ID,0)),""))
A12: EV8 | C12: Validada | D12: EJEMPLO_EV8.pdf | E12: EJEMPLO Coord. de calidad de Obstetricia | F12: 46280 | H12: EJEMPLO | I12: =IF(A12="","",IFERROR(INDEX(CONEAU_EV_EST,MATCH(A12,CONEAU_EV_ID,0)),"")) | J12: =IF(A12="","",IFERROR(INDEX(CONEAU_EV_DESC,MATCH(A12,CONEAU_EV_ID,0)),""))
A13: EV9 | C13: Disponible | D13: EJEMPLO_EV9.pdf | E13: EJEMPLO Coord. de calidad de Obstetricia | F13: 46280 | H13: EJEMPLO | I13: =IF(A13="","",IFERROR(INDEX(CONEAU_EV_EST,MATCH(A13,CONEAU_EV_ID,0)),"")) | J13: =IF(A13="","",IFERROR(INDEX(CONEAU_EV_DESC,MATCH(A13,CONEAU_EV_ID,0)),""))
A14: EV10 | C14: No iniciada | E14: EJEMPLO Coord. de calidad de Obstetricia | H14: EJEMPLO | I14: =IF(A14="","",IFERROR(INDEX(CONEAU_EV_EST,MATCH(A14,CONEAU_EV_ID,0)),"")) | J14: =IF(A14="","",IFERROR(INDEX(CONEAU_EV_DESC,MATCH(A14,CONEAU_EV_ID,0)),""))
A15: EV11 | C15: No iniciada | E15: EJEMPLO Coord. de calidad de Obstetricia | H15: EJEMPLO | I15: =IF(A15="","",IFERROR(INDEX(CONEAU_EV_EST,MATCH(A15,CONEAU_EV_ID,0)),"")) | J15: =IF(A15="","",IFERROR(INDEX(CONEAU_EV_DESC,MATCH(A15,CONEAU_EV_ID,0)),""))
A16: EV12 | C16: No iniciada | E16: EJEMPLO Coord. de calidad de Obstetricia | H16: EJEMPLO | I16: =IF(A16="","",IFERROR(INDEX(CONEAU_EV_EST,MATCH(A16,CONEAU_EV_ID,0)),"")) | J16: =IF(A16="","",IFERROR(INDEX(CONEAU_EV_DESC,MATCH(A16,CONEAU_EV_ID,0)),""))
A17: EV13 | C17: En elaboración | D17: EJEMPLO_EV13.pdf | E17: EJEMPLO Coord. de calidad de Obstetricia | F17: 46280 | H17: EJEMPLO | I17: =IF(A17="","",IFERROR(INDEX(CONEAU_EV_EST,MATCH(A17,CONEAU_EV_ID,0)),"")) | J17: =IF(A17="","",IFERROR(INDEX(CONEAU_EV_DESC,MATCH(A17,CONEAU_EV_ID,0)),""))
A18: EV14 | C18: Validada | D18: EJEMPLO_EV14.pdf | E18: EJEMPLO Coord. de calidad de Obstetricia | F18: 46280 | H18: EJEMPLO | I18: =IF(A18="","",IFERROR(INDEX(CONEAU_EV_EST,MATCH(A18,CONEAU_EV_ID,0)),"")) | J18: =IF(A18="","",IFERROR(INDEX(CONEAU_EV_DESC,MATCH(A18,CONEAU_EV_ID,0)),""))
A19: EV15 | C19: Validada | D19: EJEMPLO_EV15.pdf | E19: EJEMPLO Coord. de calidad de Obstetricia | F19: 46280 | H19: EJEMPLO | I19: =IF(A19="","",IFERROR(INDEX(CONEAU_EV_EST,MATCH(A19,CONEAU_EV_ID,0)),"")) | J19: =IF(A19="","",IFERROR(INDEX(CONEAU_EV_DESC,MATCH(A19,CONEAU_EV_ID,0)),""))
A20: EV16 | C20: Disponible | D20: EJEMPLO_EV16.pdf | E20: EJEMPLO Coord. de calidad de Obstetricia | F20: 46280 | H20: EJEMPLO | I20: =IF(A20="","",IFERROR(INDEX(CONEAU_EV_EST,MATCH(A20,CONEAU_EV_ID,0)),"")) | J20: =IF(A20="","",IFERROR(INDEX(CONEAU_EV_DESC,MATCH(A20,CONEAU_EV_ID,0)),""))
A21: EV17 | C21: Disponible | D21: EJEMPLO_EV17.pdf | E21: EJEMPLO Coord. de calidad de Obstetricia | F21: 46280 | H21: EJEMPLO | I21: =IF(A21="","",IFERROR(INDEX(CONEAU_EV_EST,MATCH(A21,CONEAU_EV_ID,0)),"")) | J21: =IF(A21="","",IFERROR(INDEX(CONEAU_EV_DESC,MATCH(A21,CONEAU_EV_ID,0)),""))
A22: EV18 | C22: Disponible | D22: EJEMPLO_EV18.pdf | E22: EJEMPLO Coord. de calidad de Obstetricia | F22: 46280 | H22: EJEMPLO | I22: =IF(A22="","",IFERROR(INDEX(CONEAU_EV_EST,MATCH(A22,CONEAU_EV_ID,0)),"")) | J22: =IF(A22="","",IFERROR(INDEX(CONEAU_EV_DESC,MATCH(A22,CONEAU_EV_ID,0)),""))
A23: EV19 | C23: En elaboración | D23: EJEMPLO_EV19.pdf | E23: EJEMPLO Coord. de calidad de Obstetricia | F23: 46280 | H23: EJEMPLO | I23: =IF(A23="","",IFERROR(INDEX(CONEAU_EV_EST,MATCH(A23,CONEAU_EV_ID,0)),"")) | J23: =IF(A23="","",IFERROR(INDEX(CONEAU_EV_DESC,MATCH(A23,CONEAU_EV_ID,0)),""))
A24: EV20 | C24: Disponible | D24: EJEMPLO_EV20.pdf | E24: EJEMPLO Coord. de calidad de Obstetricia | F24: 46280 | H24: EJEMPLO | I24: =IF(A24="","",IFERROR(INDEX(CONEAU_EV_EST,MATCH(A24,CONEAU_EV_ID,0)),"")) | J24: =IF(A24="","",IFERROR(INDEX(CONEAU_EV_DESC,MATCH(A24,CONEAU_EV_ID,0)),""))
A25: EV21 | C25: En elaboración | D25: EJEMPLO_EV21.pdf | E25: EJEMPLO Coord. de calidad de Obstetricia | F25: 46280 | H25: EJEMPLO | I25: =IF(A25="","",IFERROR(INDEX(CONEAU_EV_EST,MATCH(A25,CONEAU_EV_ID,0)),"")) | J25: =IF(A25="","",IFERROR(INDEX(CONEAU_EV_DESC,MATCH(A25,CONEAU_EV_ID,0)),""))
A26: EV22 | C26: Disponible | D26: EJEMPLO_EV22.pdf | E26: EJEMPLO Coord. de calidad de Obstetricia | F26: 46280 | H26: EJEMPLO | I26: =IF(A26="","",IFERROR(INDEX(CONEAU_EV_EST,MATCH(A26,CONEAU_EV_ID,0)),"")) | J26: =IF(A26="","",IFERROR(INDEX(CONEAU_EV_DESC,MATCH(A26,CONEAU_EV_ID,0)),""))
A27: EV23 | C27: No iniciada | E27: EJEMPLO Coord. de calidad de Obstetricia | H27: EJEMPLO | I27: =IF(A27="","",IFERROR(INDEX(CONEAU_EV_EST,MATCH(A27,CONEAU_EV_ID,0)),"")) | J27: =IF(A27="","",IFERROR(INDEX(CONEAU_EV_DESC,MATCH(A27,CONEAU_EV_ID,0)),""))
A28: EV24 | C28: Disponible | D28: EJEMPLO_EV24.pdf | E28: EJEMPLO Coord. de calidad de Obstetricia | F28: 46280 | H28: EJEMPLO | I28: =IF(A28="","",IFERROR(INDEX(CONEAU_EV_EST,MATCH(A28,CONEAU_EV_ID,0)),"")) | J28: =IF(A28="","",IFERROR(INDEX(CONEAU_EV_DESC,MATCH(A28,CONEAU_EV_ID,0)),""))
A29: EV25 | C29: En elaboración | D29: EJEMPLO_EV25.pdf | E29: EJEMPLO Coord. de calidad de Obstetricia | F29: 46280 | H29: EJEMPLO | I29: =IF(A29="","",IFERROR(INDEX(CONEAU_EV_EST,MATCH(A29,CONEAU_EV_ID,0)),"")) | J29: =IF(A29="","",IFERROR(INDEX(CONEAU_EV_DESC,MATCH(A29,CONEAU_EV_ID,0)),""))
A30: EV26 | C30: En elaboración | D30: EJEMPLO_EV26.pdf | E30: EJEMPLO Coord. de calidad de Obstetricia | F30: 46280 | H30: EJEMPLO | I30: =IF(A30="","",IFERROR(INDEX(CONEAU_EV_EST,MATCH(A30,CONEAU_EV_ID,0)),"")) | J30: =IF(A30="","",IFERROR(INDEX(CONEAU_EV_DESC,MATCH(A30,CONEAU_EV_ID,0)),""))
A31: EV27 | C31: Disponible | D31: EJEMPLO_EV27.pdf | E31: EJEMPLO Coord. de calidad de Obstetricia | F31: 46280 | H31: EJEMPLO | I31: =IF(A31="","",IFERROR(INDEX(CONEAU_EV_EST,MATCH(A31,CONEAU_EV_ID,0)),"")) | J31: =IF(A31="","",IFERROR(INDEX(CONEAU_EV_DESC,MATCH(A31,CONEAU_EV_ID,0)),""))
A32: EV28 | C32: En elaboración | D32: EJEMPLO_EV28.pdf | E32: EJEMPLO Coord. de calidad de Obstetricia | F32: 46280 | H32: EJEMPLO | I32: =IF(A32="","",IFERROR(INDEX(CONEAU_EV_EST,MATCH(A32,CONEAU_EV_ID,0)),"")) | J32: =IF(A32="","",IFERROR(INDEX(CONEAU_EV_DESC,MATCH(A32,CONEAU_EV_ID,0)),""))
A33: EV29 | C33: Disponible | D33: EJEMPLO_EV29.pdf | E33: EJEMPLO Coord. de calidad de Obstetricia | F33: 46280 | H33: EJEMPLO | I33: =IF(A33="","",IFERROR(INDEX(CONEAU_EV_EST,MATCH(A33,CONEAU_EV_ID,0)),"")) | J33: =IF(A33="","",IFERROR(INDEX(CONEAU_EV_DESC,MATCH(A33,CONEAU_EV_ID,0)),""))
A34: EV30 | C34: En elaboración | D34: EJEMPLO_EV30.pdf | E34: EJEMPLO Coord. de calidad de Obstetricia | F34: 46280 | H34: EJEMPLO | I34: =IF(A34="","",IFERROR(INDEX(CONEAU_EV_EST,MATCH(A34,CONEAU_EV_ID,0)),"")) | J34: =IF(A34="","",IFERROR(INDEX(CONEAU_EV_DESC,MATCH(A34,CONEAU_EV_ID,0)),""))
A35: EV31 | C35: Validada | D35: EJEMPLO_EV31.pdf | E35: EJEMPLO Coord. de calidad de Obstetricia | F35: 46280 | H35: EJEMPLO | I35: =IF(A35="","",IFERROR(INDEX(CONEAU_EV_EST,MATCH(A35,CONEAU_EV_ID,0)),"")) | J35: =IF(A35="","",IFERROR(INDEX(CONEAU_EV_DESC,MATCH(A35,CONEAU_EV_ID,0)),""))
A36: EV32 | C36: Disponible | D36: EJEMPLO_EV32.pdf | E36: EJEMPLO Coord. de calidad de Obstetricia | F36: 46280 | H36: EJEMPLO | I36: =IF(A36="","",IFERROR(INDEX(CONEAU_EV_EST,MATCH(A36,CONEAU_EV_ID,0)),"")) | J36: =IF(A36="","",IFERROR(INDEX(CONEAU_EV_DESC,MATCH(A36,CONEAU_EV_ID,0)),""))
A37: EV33 | C37: Disponible | D37: EJEMPLO_EV33.pdf | E37: EJEMPLO Coord. de calidad de Obstetricia | F37: 46280 | H37: EJEMPLO | I37: =IF(A37="","",IFERROR(INDEX(CONEAU_EV_EST,MATCH(A37,CONEAU_EV_ID,0)),"")) | J37: =IF(A37="","",IFERROR(INDEX(CONEAU_EV_DESC,MATCH(A37,CONEAU_EV_ID,0)),""))
A38: EV34 | C38: En elaboración | D38: EJEMPLO_EV34.pdf | E38: EJEMPLO Coord. de calidad de Obstetricia | F38: 46280 | H38: EJEMPLO | I38: =IF(A38="","",IFERROR(INDEX(CONEAU_EV_EST,MATCH(A38,CONEAU_EV_ID,0)),"")) | J38: =IF(A38="","",IFERROR(INDEX(CONEAU_EV_DESC,MATCH(A38,CONEAU_EV_ID,0)),""))
A39: EV35 | C39: Disponible | D39: EJEMPLO_EV35.pdf | E39: EJEMPLO Coord. de calidad de Obstetricia | F39: 46280 | H39: EJEMPLO | I39: =IF(A39="","",IFERROR(INDEX(CONEAU_EV_EST,MATCH(A39,CONEAU_EV_ID,0)),"")) | J39: =IF(A39="","",IFERROR(INDEX(CONEAU_EV_DESC,MATCH(A39,CONEAU_EV_ID,0)),""))
A40: EV36 | C40: No iniciada | E40: EJEMPLO Coord. de calidad de Obstetricia | H40: EJEMPLO | I40: =IF(A40="","",IFERROR(INDEX(CONEAU_EV_EST,MATCH(A40,CONEAU_EV_ID,0)),"")) | J40: =IF(A40="","",IFERROR(INDEX(CONEAU_EV_DESC,MATCH(A40,CONEAU_EV_ID,0)),""))
A41: EV37 | C41: Disponible | D41: EJEMPLO_EV37.pdf | E41: EJEMPLO Coord. de calidad de Obstetricia | F41: 46280 | H41: EJEMPLO | I41: =IF(A41="","",IFERROR(INDEX(CONEAU_EV_EST,MATCH(A41,CONEAU_EV_ID,0)),"")) | J41: =IF(A41="","",IFERROR(INDEX(CONEAU_EV_DESC,MATCH(A41,CONEAU_EV_ID,0)),""))
...

Sheet Alcance
A1: Alcance: qué indicadores vigila esta escuela
A2: Sí: el tablero espera datos y alerta si faltan. No: se deja fuera (fase posterior). Valor inicial según 'alcance_inicial' [CP]: indicadores del piloto, de los 9 procesos del 10.2 y los 29 del modelo.
A4: indicador_id | B4: en_seguimiento | C4: responsable_local | D4: nota | E4: nombre
A5: ID1 | B5: Sí | E5: =IFERROR(INDEX(Catalogo!$C$5:$C$129,MATCH(A5,Catalogo!$A$5:$A$129,0)),"")
A6: ID2 | B6: Sí | E6: =IFERROR(INDEX(Catalogo!$C$5:$C$129,MATCH(A6,Catalogo!$A$5:$A$129,0)),"")
A7: ID3 | B7: Sí | E7: =IFERROR(INDEX(Catalogo!$C$5:$C$129,MATCH(A7,Catalogo!$A$5:$A$129,0)),"")
A8: ID4 | B8: Sí | E8: =IFERROR(INDEX(Catalogo!$C$5:$C$129,MATCH(A8,Catalogo!$A$5:$A$129,0)),"")
A9: ID5 | B9: Sí | E9: =IFERROR(INDEX(Catalogo!$C$5:$C$129,MATCH(A9,Catalogo!$A$5:$A$129,0)),"")
A10: ID6 | B10: Sí | E10: =IFERROR(INDEX(Catalogo!$C$5:$C$129,MATCH(A10,Catalogo!$A$5:$A$129,0)),"")
A11: ID7 | B11: Sí | E11: =IFERROR(INDEX(Catalogo!$C$5:$C$129,MATCH(A11,Catalogo!$A$5:$A$129,0)),"")
A12: ID8 | B12: Sí | E12: =IFERROR(INDEX(Catalogo!$C$5:$C$129,MATCH(A12,Catalogo!$A$5:$A$129,0)),"")
A13: ID9 | B13: Sí | E13: =IFERROR(INDEX(Catalogo!$C$5:$C$129,MATCH(A13,Catalogo!$A$5:$A$129,0)),"")
A14: ID10 | B14: Sí | E14: =IFERROR(INDEX(Catalogo!$C$5:$C$129,MATCH(A14,Catalogo!$A$5:$A$129,0)),"")
A15: ID11 | B15: Sí | E15: =IFERROR(INDEX(Catalogo!$C$5:$C$129,MATCH(A15,Catalogo!$A$5:$A$129,0)),"")
A16: ID12 | B16: Sí | E16: =IFERROR(INDEX(Catalogo!$C$5:$C$129,MATCH(A16,Catalogo!$A$5:$A$129,0)),"")
... A129: PEFM-AE.04.02 | B129: Solo Facultad | E129: =IFERROR(INDEX(Catalogo!$C$5:$C$129,MATCH(A129,Catalogo!$A$5:$A$129,0)),"")

Sheet Criterios
A1: Autoevaluación por criterio (53 criterios del modelo CONEAU 2026)
A2: Misma lista para las tres escuelas. Llena lo que diga el informe de autoevaluación de la escuela; sin informe, deja «sin dato». Alimenta las alertas R12 (EV exigidas sin citar) y R13 (matrices pendientes).
A4: escuela | B4: estandar | C4: criterio | D4: resumen | E4: valoracion_informe | F4: ev_exigidas | G4: ev_exigidas_sin_citar | H4: matrices_pendientes | I4: prioridad | J4: indicadores_que_lo_citan | K4: evidencias_citadas | L4: con_enlace | M4: evidencia_que_falta | N4: archivo | O4: fuente | P4: origen
A5: =IF(Portada!$B$7="","",Portada!$B$7) | B5: E1 | C5: 1.1 | D5: Estructura interna pertinente | E5: sin dato | F5: EV1
A6: =IF(Portada!$B$7="","",Portada!$B$7) | B6: E1 | C6: 1.2 | D6: Cuerpo directivo idóneo | E6: sin dato | F6: EV2
A7: =IF(Portada!$B$7="","",Portada!$B$7) | B7: E1 | C7: 1.3 | D7: Planes con objetivos académicos evaluados anualmente | E7: sin dato | F7: EV3 EV4 EV5 EV6
A8: =IF(Portada!$B$7="","",Portada!$B$7) | B8: E1 | C8: 1.4 | D8: Quejas, reclamos y denuncias | E8: sin dato | F8: EV7
A9: =IF(Portada!$B$7="","",Portada!$B$7) | B9: E1 | C9: 1.5 | D9: Satisfacción con servicios administrativos | E9: sin dato | F9: EV7 EV41 EV42 EV43 | J9: ID8 ID18 ID21
A10: =IF(Portada!$B$7="","",Portada!$B$7) | B10: E2 | C10: 2.1 | D10: Componentes mínimos del currículo | E10: sin dato | F10: EV8 | J10: ID1 ID12
A11: =IF(Portada!$B$7="","",Portada!$B$7) | B11: E2 | C11: 2.2 | D11: Perfil de egreso | E11: sin dato | F11: EV8
A12: =IF(Portada!$B$7="","",Portada!$B$7) | B12: E2 | C12: 2.3 | D12: Plan de estudios completo | E12: sin dato | F12: EV8
A13: =IF(Portada!$B$7="","",Portada!$B$7) | B13: E2 | C13: 2.4 | E13: sin dato | F13: EV9
A14: =IF(Portada!$B$7="","",Portada!$B$7) | B14: E2 | C14: 2.5 | D14: Contenido de los sílabos | E14: sin dato | F14: EV9
A15: =IF(Portada!$B$7="","",Portada!$B$7) | B15: E2 | C15: 2.6 | D15: Normas de convalidación | E15: sin dato | F15: EV11
A16: =IF(Portada!$B$7="","",Portada!$B$7) | B16: E2 | C16: 2.7 | D16: Verificación del cumplimiento de sílabos | E16: sin dato | F16: EV10 | J16: ID11
A17: =IF(Portada!$B$7="","",Portada!$B$7) | B17: E3 | C17: 3.1 | D17: Evaluación de la calidad de la enseñanza | E17: sin dato | F17: EV12 | J17: ID1 ID3 ID4 ID10 ID19 ID22
A18: =IF(Portada!$B$7="","",Portada!$B$7) | B18: E3 | C18: 3.2 | D18: Evaluación coherente con el enfoque pedagógico | E18: sin dato | F18: EV13 | J18: ID4
A19: =IF(Portada!$B$7="","",Portada!$B$7) | B19: E3 | C19: 3.3 | D19: Evidencias del logro del perfil | E19: sin dato | F19: EV13 EV17 | J19: ID4 ID20
A20: =IF(Portada!$B$7="","",Portada!$B$7) | B20: E3 | C20: 3.4 | D20: Información oportuna al estudiante | E20: sin dato | F20: EV13 | J20: ID4
A21: =IF(Portada!$B$7="","",Portada!$B$7) | B21: E3 | C21: 3.5 | D21: Tutoría y asesoría | E21: sin dato | F21: EV14 EV15 EV18 | J21: ID5 ID9 ID24
A22: =IF(Portada!$B$7="","",Portada!$B$7) | B22: E3 | C22: 3.6 | D22: Originalidad y rigor de tesis | E22: sin dato | F22: EV16 EV19
A23: =IF(Portada!$B$7="","",Portada!$B$7) | B23: E3 | C23: 3.7 | D23: Autoría del propio estudiante | E23: sin dato | F23: EV16
A24: =IF(Portada!$B$7="","",Portada!$B$7) | B24: E4 | C24: 4.1 | D24: Selección y vinculación transparente | E24: sin dato | F24: EV20 EV22 EV24 | J24: ID4 ID14 ID19
A25: =IF(Portada!$B$7="","",Portada!$B$7) | B25: E4 | C25: 4.2 | D25: Competencias pedagógicas, disciplinares y digitales | E25: sin dato | F25: EV21 EV24 EV25 | J25: ID2 ID19
A26: =IF(Portada!$B$7="","",Portada!$B$7) | B26: E4 | C26: 4.3 | D26: Carga lectiva según perfil docente | E26: sin dato | F26: EV23 EV24 | J26: ID2 ID13 ID14
A27: =IF(Portada!$B$7="","",Portada!$B$7) | B27: E4 | C27: 4.4 | D27: Evaluación periódica del desempeño | E27: sin dato | F27: EV21 EV25 | J27: ID2 ID15 ID16 ID19
A28: =IF(Portada!$B$7="","",Portada!$B$7) | B28: E4 | C28: 4.5 | D28: Fortalecimiento de capacidades | E28: sin dato | F28: EV26 EV27 | J28: ID15 ID16
A29: =IF(Portada!$B$7="","",Portada!$B$7) | B29: E4 | C29: 4.6 | D29: Experiencias en otras instituciones | E29: sin dato | F29: EV28 EV29 | J29: ID14
A30: =IF(Portada!$B$7="","",Portada!$B$7) | B30: E5 | C30: 5.1 | D30: Infraestructura suficiente y adecuada | E30: sin dato | F30: EV30 | J30: ID3 ID17
A31: =IF(Portada!$B$7="","",Portada!$B$7) | B31: E5 | C31: 5.2 | D31: Equipamiento y mobiliario | E31: sin dato | F31: EV30 | J31: ID3 ID17
A32: =IF(Portada!$B$7="","",Portada!$B$7) | B32: E5 | C32: 5.3 | D32: Tecnologías de información | E32: sin dato | F32: EV30 | J32: ID3 ID17
A33: =IF(Portada!$B$7="","",Portada!$B$7) | B33: E5 | C33: 5.4 | D33: Protocolos y manuales | E33: sin dato | F33: EV31
A34: =IF(Portada!$B$7="","",Portada!$B$7) | B34: E5 | C34: 5.5 | D34: Recursos académicos y bases de datos | E34: sin dato | F34: EV32 | J34: ID3 ID17
A35: =IF(Portada!$B$7="","",Portada!$B$7) | B35: E5 | C35: 5.6 | D35: Plan de mantenimiento | E35: sin dato | F35: EV33
A36: =IF(Portada!$B$7="","",Portada!$B$7) | B36: E6 | C36: 6.1 | D36: Currículo con impacto positivo | E36: sin dato | F36: EV34 EV35 | J36: ID10 ID20 ID26 ID27 ID28 ID29
A37: =IF(Portada!$B$7="","",Portada!$B$7) | B37: E6 | C37: 6.2 | D37: Impacto en egresados (cinco años) | E37: sin dato | F37: EV34 | J37: ID20 ID22 ID26 ID27 ID28 ID29
A38: =IF(Portada!$B$7="","",Portada!$B$7) | B38: E6 | C38: 6.3 | D38: Consulta a empleadores | E38: sin dato | F38: EV35 | J38: ID26 ID27 ID28 ID29
A39: =IF(Portada!$B$7="","",Portada!$B$7) | B39: E6 | C39: 6.4 | D39: Planes de mejora | E39: sin dato | F39: EV36
A40: =IF(Portada!$B$7="","",Portada!$B$7) | B40: E6 | C40: 6.5 | D40: Procedimientos en el SGC | E40: sin dato | F40: EV36
A41: =IF(Portada!$B$7="","",Portada!$B$7) | B41: E7 | C41: 7.1 | D41: Programas de bienestar | E41: sin dato | F41: EV37
...

Sheet Valores_informe
A1: Valores de los 29 indicadores en el informe de autoevaluación (solo referencia)
A2: Misma lista para las tres escuelas. Son los valores que trae el informe, sin validar: no intervienen en semáforos, alertas ni gráficos. El referencial es el del Modelo CONEAU 2026 [A4].
A4: escuela | B4: indicador_id | C4: nombre | D4: unidad_modelo | E4: valor_informe | F4: referencial | G4: referencial_texto | H4: fuente_referencial | I4: referencial_en_informe | J4: estado_que_declara_el_informe | K4: calculo | L4: observacion | M4: estado | N4: uso | O4: archivo | P4: fuente | Q4: origen
A5: =IF(Portada!$B$7="","",Portada!$B$7) | B5: ID1 | C5: Porcentaje de estudiantes satisfechos con el currículo | D5: % | F5: 60 | G5: 60% | H5: Modelo CONEAU 2026 [A4] | M5: =IF(E5="","sin dato","Sin dato validado") | N5: Solo referencia: no interviene en semáforos, alertas ni gráficos
A6: =IF(Portada!$B$7="","",Portada!$B$7) | B6: ID2 | C6: Porcentaje de estudiantes satisfechos con el desempeño docente | D6: % | F6: 70 | G6: 70% | H6: Modelo CONEAU 2026 [A4] | M6: =IF(E6="","sin dato","Sin dato validado") | N6: Solo referencia: no interviene en semáforos, alertas ni gráficos
A7: =IF(Portada!$B$7="","",Portada!$B$7) | B7: ID3 | C7: Porcentaje de estudiantes satisfechos con los recursos para la enseñanza-aprendizaje | D7: % | F7: 70 | G7: 70% | H7: Modelo CONEAU 2026 [A4] | M7: =IF(E7="","sin dato","Sin dato validado") | N7: Solo referencia: no interviene en semáforos, alertas ni gráficos
A8: =IF(Portada!$B$7="","",Portada!$B$7) | B8: ID4 | C8: Porcentaje de estudiantes satisfechos con la evaluación del aprendizaje | D8: % | F8: 60 | G8: 60% | H8: Modelo CONEAU 2026 [A4] | M8: =IF(E8="","sin dato","Sin dato validado") | N8: Solo referencia: no interviene en semáforos, alertas ni gráficos
A9: =IF(Portada!$B$7="","",Portada!$B$7) | B9: ID5 | C9: Porcentaje de estudiantes satisfechos con la asesoría o tutoría para la obtención del título | D9: % | F9: 70 | G9: 70% | H9: Modelo CONEAU 2026 [A4] | M9: =IF(E9="","sin dato","Sin dato validado") | N9: Solo referencia: no interviene en semáforos, alertas ni gráficos
A10: =IF(Portada!$B$7="","",Portada!$B$7) | B10: ID6 | C10: Evolución del porcentaje de postulantes al programa | D10: % | F10: 0 | G10: 0% (valor referencial del texto) | H10: Modelo CONEAU 2026 [A4] | M10: =IF(E10="","sin dato","Sin dato validado") | N10: Solo referencia: no interviene en semáforos, alertas ni gráficos
A11: =IF(Portada!$B$7="","",Portada!$B$7) | B11: ID7 | C11: Porcentaje de estudiantes satisfechos con los programas de bienestar y actividades recreativas, culturales, artísticas y deportivas | D11: % | F11: 70 | G11: 70% | H11: Modelo CONEAU 2026 [A4] | M11: =IF(E11="","sin dato","Sin dato validado") | N11: Solo referencia: no interviene en semáforos, alertas ni gráficos
A12: =IF(Portada!$B$7="","",Portada!$B$7) | B12: ID8 | C12: Porcentaje de estudiantes satisfechos con los procedimientos de los servicios administrativos | D12: % | F12: 60 | G12: 60% | H12: Modelo CONEAU 2026 [A4] | M12: =IF(E12="","sin dato","Sin dato validado") | N12: Solo referencia: no interviene en semáforos, alertas ni gráficos
A13: =IF(Portada!$B$7="","",Portada!$B$7) | B13: ID9 | C13: Porcentaje de estudiantes satisfechos con los servicios de apoyo pedagógico | D13: % | F13: 70 | G13: 70% | H13: Modelo CONEAU 2026 [A4] | M13: =IF(E13="","sin dato","Sin dato validado") | N13: Solo referencia: no interviene en semáforos, alertas ni gráficos
